Workbook
Name d: #REF!
Name DBZ: #REF!

Sheet MAYO 02 2026
D1: CAJA MENOR
A7: FECHA | B7: CEDULA(NIT) | C7: NOMBRE | D7: FUNCIONARIO | E7: DESCRIPCIÓN O DETALLE | F7: NIT | G7: PROVEEDOR
H10: ='[1]ABRIL 30 2026'!$H$22 -> -943606.44
A12: 46058 | B12: 13239826 | C12: EDISON LEAL | D12: RECEPCION | E12: ALMUERZO SABADO | F12: 13239826 | G12: EDISON LEAL | H12: 14000
A13: 46058 | B13: 13239826 | C13: EDISON LEAL | D13: RECEPCION | E13: TRANSPORTE JUGOS DE MAKRO A HORNEADOS Y LEON | F13: 13239826 | G13: EDISON LEAL | H13: 24000
A14: 46058 | B14: 13239826 | C14: EDISON LEAL | D14: RECEPCION | E14: TRANSPORTE PACAS DE AGUA BOTELLA INDEPORTE, PARQUE DEPORTIVO | F14: 13239826 | G14: EDISON LEAL | H14: 24000
A15: 46058 | B15: 14236999 | C15: JAIRO ARIAS | D15: PRODUCCION | E15: COMPRA ESPONJA ETERNA | F15: 14236999 | G15: JAIRO ARIAS | H15: 3600
A16: 46058 | B16: 65762110 | C16: SANDRA BONILLA | D16: CONTRATACION | E16: ALMUERZO SABADO | F16: 65762110 | G16: SANDRA BONILLA | H16: 14000
A17: 46058 | B17: 65737477 | C17: SANDRA GALLEGO | D17: RECEPCION | E17: COMPRA DE ACEITE EVENTO KIDS | F17: 901768321-4 | G17: ARCINIEGAS ASOCIADOS | H17: 20000
A18: 46058 | B18: 65737477 | C18: SANDRA GALLEGO | D18: RECEPCION | E18: COMPRA MAIZ PIRA EVENTO KIDS | F18: 9000592385 | G18: MAKRO | H18: 13200
A19: 46058 | B19: 1110511708 | C19: FABIAN PEREZ | D19: INGENIERO | E19: ENVIO ELECTRONICA/ CARLOS ANDRES TORRES SISTEMA | F19: 8300514407 | G19: EXXE LOGISTICA SAS | H19: 24668
H21: =SUM(H12:H19) -> 137468
H23: =H10-H21 -> -1081074.4
B26: 110580597 | C26: WILIAN FELIPE | D26: PLANEACION
B27: 65777220 | C27: MAGDA TAFUR | D27: COMPRAS
B28: 65737477 | C28: SANDRA GALLEGO | D28: RECEPCION
B29: 14106438 | C29: DIEGO RADA | D29: CONTRATACION
B30: 5939109 | C30: MIRVEAN HERNANDEZ | D30: LOGISTICA
B31: 13239826 | C31: EDISON LEAL | D31: RECEPCION
B32: 65762110 | C32: SANDRA BONILLA | D32: CONTRATACION
B33: 1032372158 | C33: HAROLD FERIAS | D33: LOGISTICA
B34: 1110511708 | C34: FABIAN PEREZ | D34: INGENIERO
B35: 1110546445 | C35: MARIO GARCIA | D35: LOSGISTICA
B36: 1006123077 | C36: JOHAN GARZON | D36: AUXILIAR L.
B37: 14236999 | C37: JAIRO ARIAS | D37: PRODUCCION
... B42: 1007832826 | C42: SEBASTIAN GONGORA | D42: PLANIACION
B43: 800185306-4 | C43: ENVIA
B44: 1110546445 | C44: MARIO GARCIA | D44: LOSGISTICA
B45: 1005717607 | C45: JIMY GUTIERREZ | D45: LOSGISTICA
B46: 14243741 | C46: JUAN HORTA | D46: PRODUCCION
B47: 1110442630 | C47: JERSSON OROZCO | D47: LOGISTICA
B48: 900276962-1 | C48: D1 SAS
B49: 800251569 | C49: INTERRAPIDISOMO
B50: 1006122533 | C50: LAURA MARIN | D50: COMUNICADORA

Sheet MAYO 03 2026
D1: CAJA MENOR
A7: FECHA | B7: CEDULA(NIT) | C7: NOMBRE | D7: FUNCIONARIO | E7: DESCRIPCIÓN O DETALLE | F7: NIT | G7: PROVEEDOR
H10: ='MAYO 02 2026'!H23 -> -1081074.4
A12: 46117 | B12: 65762110 | C12: SANDRA BONILLA | D12: CONTRATACION | E12: TAXI 2 EVENTO PALOMA | F12: 65762110 | G12: SANDRA BONILLA | H12: 20000
A13: 46117 | B13: 65762110 | C13: SANDRA BONILLA | D13: CONTRATACION | E13: TRANSPORTE LLEVADA ROBAEGALLO SEDE PALOMA (6000X2) | F13: 65762110 | G13: SANDRA BONILLA | H13: 12000
A14: 46117 | B14: 65737477 | C14: SANDRA GALLEGO | D14: RECEPCION | E14: TRANSPORTE MEDICADIZ LEON | F14: 65737477 | G14: SANDRA GALLEGO | H14: 17800
A15: 46117 | B15: 1007832826 | C15: SEBASTIAN GONGORA | D15: PLANIACION | E15: TRANSPORTE PANOPTICO 19 ABRIL | F15: 1007832826 | G15: SEBASTIAN GONGORA | H15: 7600
A16: 46117 | B16: 1007832826 | C16: SEBASTIAN GONGORA | D16: PLANIACION | E16: CINTA GRIS KIDS | F16: 1007832826 | G16: SEBASTIAN GONGORA | H16: 15000
A17: 46117 | B17: 1007832826 | C17: SEBASTIAN GONGORA | D17: PLANIACION | E17: ALMUERZO VIERNES KIDS | F17: 1007832826 | G17: SEBASTIAN GONGORA | H17: 14000
A18: 46117 | B18: 65737477 | C18: SANDRA GALLEGO | D18: RECEPCION | E18: TRANSPORTE FR MEDICADIZ- MEDICADIZ FR | F18: 65737477 | G18: SANDRA GALLEGO | H18: 36700
A19: 46117 | B19: 1007832826 | C19: SEBASTIAN GONGORA | D19: PLANIACION | E19: IMPRESIONES TEATRO KIDS | F19: 1007832826 | G19: SEBASTIAN GONGORA | H19: 7000
A20: 46117 | B20: 1110511708 | C20: FABIAN PEREZ | D20: INGENIERO | E20: SERVICIO MOVISTAR | F20: 830122566-1 | G20: TELECOMUNICACIONES ESP BIC | H20: 5000
A21: 46117 | B21: 1110511708 | C21: FABIAN PEREZ | D21: INGENIERO | E21: SERVICIO MOVISTAR | F21: 830122566-1 | G21: TELECOMUNICACIONES ESP BIC | H21: 25000
A22: 46117 | B22: 14236999 | C22: JAIRO ARIAS | D22: PRODUCCION | E22: COMPRA DE VARSOL GALON | F22: 900931946-1 | G22: COMERCIALIZADORA QUEN SAS | H22: 30255
A23: 46117 | B23: 65737477 | C23: SANDRA GALLEGO | D23: RECEPCION | E23: CERA DE GEL GERENCIA | F23: 19474458-2 | G23: LECHE PAL PELO | H23: 28500
A24: 46117 | B24: 13239826 | C24: EDISON LEAL | D24: RECEPCION | E24: PARQUEADERO MENSAJERO | F24: AP 91579 | G24: PARQUEADRO LA TERTULIA | H24: 900
A25: 46117 | B25: 1007832826 | C25: SEBASTIAN GONGORA | D25: PLANIACION | E25: SERVICIO RESTAURANTE | F25: 98488052-4 | G25: PARRILLA SABOR COLOMBIANO | H25: 10000
A26: 46117 | B26: 65777220 | C26: MAGDA TAFUR | D26: COMPRAS | E26: ENVIO SOUND TRACK IMSTARTACIONES | F26: 800251569 | G26: INTERRAPIDISOMO | H26: 35900
H28: =SUM(H12:H26) -> 265655
H30: =H10-H28 -> -1346729.4
B33: 110580597 | C33: WILIAN FELIPE | D33: PLANEACION
B34: 65777220 | C34: MAGDA TAFUR | D34: COMPRAS
B35: 65737477 | C35: SANDRA GALLEGO | D35: RECEPCION
B36: 14106438 | C36: DIEGO RADA | D36: CONTRATACION
B37: 5939109 | C37: MIRVEAN HERNANDEZ | D37: LOGISTICA
B38: 13239826 | C38: EDISON LEAL | D38: RECEPCION
B39: 65762110 | C39: SANDRA BONILLA | D39: CONTRATACION
B40: 1032372158 | C40: HAROLD FERIAS | D40: LOGISTICA
B41: 1110511708 | C41: FABIAN PEREZ | D41: INGENIERO
B42: 1110546445 | C42: MARIO GARCIA | D42: LOSGISTICA
B43: 1006123077 | C43: JOHAN GARZON | D43: AUXILIAR L.
B44: 14236999 | C44: JAIRO ARIAS | D44: PRODUCCION
... B49: 1007832826 | C49: SEBASTIAN GONGORA | D49: PLANIACION
B50: 800185306-4 | C50: ENVIA
B51: 1110546445 | C51: MARIO GARCIA | D51: LOSGISTICA
B52: 1005717607 | C52: JIMY GUTIERREZ | D52: LOSGISTICA
B53: 14243741 | C53: JUAN HORTA | D53: PRODUCCION
B54: 1110442630 | C54: JERSSON OROZCO | D54: LOGISTICA
B55: 900276962-1 | C55: D1 SAS
B56: 800251569 | C56: INTERRAPIDISOMO
...

Sheet MAYO 05 2026
D1: CAJA MENOR
A7: FECHA | B7: CEDULA(NIT) | C7: NOMBRE | D7: FUNCIONARIO | E7: DESCRIPCIÓN O DETALLE | F7: NIT | G7: PROVEEDOR
H10: ='MAYO 03 2026'!H30 -> -1346729.4
A12: 46147 | B12: 65737477 | C12: SANDRA GALLEGO | D12: RECEPCION | E12: TRANSPORTE RECOGER TROPEZON CONFENALCO | F12: 65737477 | G12: SANDRA GALLEGO | H12: 20000
A13: 46147 | B13: 1234638696 | C13: GIOUANNI HURTADO | D13: LOGISTICA | E13: INSTACREM*144G EVENTO SECRETARIA DE LA MUJER | F13: 901768321-4 | G13: ARCINIEGAS ASOCIADOS SP S.A.S | H13: 9450
A14: 46147 | B14: 1007832826 | C14: SEBASTIAN GONGORA | D14: PLANIACION | E14: DESAYUNO GOBERNACION | F14: 901006707-4 | G14: MORATA | H14: 18700
A15: 46147 | B15: 65737477 | C15: SANDRA GALLEGO | D15: RECEPCION | E15: TOALLA DE COCINA REN PRODUCCION IN | F15: 900276962-1 | G15: D1 | H15: 21000
H17: =SUM(H12:H15) -> 69150
H19: =H10-H17 -> -1415879.4
B22: 110580597 | C22: WILIAN FELIPE | D22: PLANEACION
B23: 65777220 | C23: MAGDA TAFUR | D23: COMPRAS
B24: 65737477 | C24: SANDRA GALLEGO | D24: RECEPCION
B25: 14106438 | C25: DIEGO RADA | D25: CONTRATACION
B26: 5939109 | C26: MIRVEAN HERNANDEZ | D26: LOGISTICA
B27: 13239826 | C27: EDISON LEAL | D27: RECEPCION
B28: 65762110 | C28: SANDRA BONILLA | D28: CONTRATACION
B29: 1032372158 | C29: HAROLD FERIAS | D29: LOGISTICA
B30: 1110511708 | C30: FABIAN PEREZ | D30: INGENIERO
B31: 1110546445 | C31: MARIO GARCIA | D31: LOSGISTICA
B32: 1006123077 | C32: JOHAN GARZON | D32: AUXILIAR L.
B33: 14236999 | C33: JAIRO ARIAS | D33: PRODUCCION
... B38: 1007832826 | C38: SEBASTIAN GONGORA | D38: PLANIACION
B39: 800185306-4 | C39: ENVIA
B40: 1110546445 | C40: MARIO GARCIA | D40: LOSGISTICA
B41: 1005717607 | C41: JIMY GUTIERREZ | D41: LOSGISTICA
B42: 14243741 | C42: JUAN HORTA | D42: PRODUCCION
B43: 1110442630 | C43: JERSSON OROZCO | D43: LOGISTICA
B44: 900276962-1 | C44: D1 SAS
B45: 800251569 | C45: INTERRAPIDISOMO
B46: 1006122533 | C46: LAURA MARIN | D46: COMUNICADORA

Sheet MAYO 06 2026 
D1: CAJA MENOR
A7: FECHA | B7: CEDULA(NIT) | C7: NOMBRE | D7: FUNCIONARIO | E7: DESCRIPCIÓN O DETALLE | F7: NIT | G7: PROVEEDOR
H10: ='MAYO 05 2026'!H19 -> -1415879.4
A12: 46178 | B12: 65777220 | C12: MAGDA TAFUR | D12: COMPRAS | E12: TRASNPORTE COMPREAS GERENCIA | F12: 65777220 | G12: MAGDA TAFUR | H12: 6000
A13: 46178 | B13: 65737477 | C13: SANDRA GALLEGO | D13: RECEPCION | E13: DOMICILIO CORTOLIMA | F13: 65737477 | G13: SANDRA GALLEGO | H13: 8000
A14: 46178 | B14: 65737477 | C14: SANDRA GALLEGO | D14: RECEPCION | E14: MILOS ADMINISTRATIVOS | F14: 65737477 | G14: SANDRA GALLEGO | H14: 5000
A15: 46178 | B15: 13239826 | C15: EDISON LEAL | D15: RECEPCION | E15: RETIRO EFECTIVO | F15: 13239826 | G15: EDISON LEAL | H15: 29750
A16: 46178 | B16: 65737477 | C16: SANDRA GALLEGO | D16: RECEPCION | E16: MEDICAMENTO NATURAL GERENCIA | F16: 65744437-4 | G16: TIENDA NATURISTA FLOR DE LA SALUD | H16: 40000
A17: 46178 | B17: 65737477 | C17: SANDRA GALLEGO | D17: RECEPCION | E17: MEDICAMENTO GERENCIA | F17: 800149695-1 | G17: CRUZVERDE+ | H17: 22000
A18: 46178 | B18: 65777220 | C18: MAGDA TAFUR | D18: COMPRAS | E18: VENTILADOR CONTRATACION | F18: 901936339-7 | G18: FORTUNA ARISTI | H18: 49000
A19: 46178 | B19: 13239826 | C19: EDISON LEAL | D19: RECEPCION | E19: PARQUEADERO MENSAJERO | F19: 900206296-3 | G19: PARQUEADERO EDIFICIO FONTAINEBLEAU | H19: 1700
A20: 46178 | B20: 13239826 | C20: EDISON LEAL | D20: RECEPCION | E20: PARQUEADERO MENSAJERO | F20: 900018771 | G20: PARQUEADERO CENTRO COMERCIAL MULTICENTRO | H20: 2200
A21: 46178 | B21: 1234638696 | C21: GIOUANNI HURTADO | D21: LOGISTICA | E21: EVENTO TALENTO KIDS | F21: 901370428-3 | G21: SUPERMERCADO MERCACENTRO | H21: 21200
A22: 46178 | B22: 1234638696 | C22: GIOUANNI HURTADO | D22: LOGISTICA | E22: EVENTO TALENTO KIDS | F22: 901370428-3 | G22: SUPERMERCADO MERCACENTRO | H22: 24700
H23: =SUM(H12:H22) -> 209550
H25: =H10-H23 -> -1625429.4
B28: 110580597 | C28: WILIAN FELIPE | D28: PLANEACION
B29: 65777220 | C29: MAGDA TAFUR | D29: COMPRAS
B30: 65737477 | C30: SANDRA GALLEGO | D30: RECEPCION
B31: 14106438 | C31: DIEGO RADA | D31: CONTRATACION
B32: 5939109 | C32: MIRVEAN HERNANDEZ | D32: LOGISTICA
B33: 13239826 | C33: EDISON LEAL | D33: RECEPCION
B34: 65762110 | C34: SANDRA BONILLA | D34: CONTRATACION
B35: 1032372158 | C35: HAROLD FERIAS | D35: LOGISTICA
B36: 1110511708 | C36: FABIAN PEREZ | D36: INGENIERO
B37: 1110546445 | C37: MARIO GARCIA | D37: LOSGISTICA
B38: 1006123077 | C38: JOHAN GARZON | D38: AUXILIAR L.
B39: 14236999 | C39: JAIRO ARIAS | D39: PRODUCCION
... B44: 1007832826 | C44: SEBASTIAN GONGORA | D44: PLANIACION
B45: 800185306-4 | C45: ENVIA
B46: 1110546445 | C46: MARIO GARCIA | D46: LOSGISTICA
B47: 1005717607 | C47: JIMY GUTIERREZ | D47: LOSGISTICA
B48: 14243741 | C48: JUAN HORTA | D48: PRODUCCION
B49: 1110442630 | C49: JERSSON OROZCO | D49: LOGISTICA
B50: 900276962-1 | C50: D1 SAS
B51: 800251569 | C51: INTERRAPIDISOMO
B52: 1006122533 | C52: LAURA MARIN | D52: COMUNICADORA

Sheet MAYO 07 2026  
D1: CAJA MENOR
A7: FECHA | B7: CEDULA(NIT) | C7: NOMBRE | D7: FUNCIONARIO | E7: DESCRIPCIÓN O DETALLE | F7: NIT | G7: PROVEEDOR
H10: ='MAYO 06 2026 '!H25 -> -1625429.4
A12: 46208 | B12: 14106438 | C12: DIEGO RADA | D12: CONTRATACION | E12: TESORERIA Y GOBERNACION | F12: 14106438 | G12: DIEGO RADA | H12: 30000
A13: 46208 | B13: 13239826 | C13: EDISON LEAL | D13: RECEPCION | E13: TRANSPORTE MERCACENTRO | F13: 13239826 | G13: EDISON LEAL | H13: 19600
A14: 46208 | B14: 65777220 | C14: MAGDA TAFUR | D14: COMPRAS | E14: TRANSPORTE PARQUE MURILLO LEON | F14: 65777220 | G14: MAGDA TAFUR | H14: 30000
A15: 46208 | B15: 1234638696 | C15: GIOUANNI HURTADO | D15: LOGISTICA | E15: TRASNPORTE LLEVAR AGUA GOBERNACION | F15: 1234638696 | G15: GIOUANNI HURTADO | H15: 10200
A16: 46208 | B16: 14106438 | C16: DIEGO RADA | D16: CONTRATACION | E16: TESORERIA Y GOBERNACION | F16: 14106438 | G16: DIEGO RADA | H16: 30000
A17: 46208 | B17: 65737477 | C17: SANDRA GALLEGO | D17: RECEPCION | E17: DOMICILIO CARNAVAL DEL POLLO | F17: 65737477 | G17: SANDRA GALLEGO | H17: 6000
A18: 46208 | B18: 65777220 | C18: MAGDA TAFUR | D18: COMPRAS | E18: CAMBIO DE CREMALLERA MALETA NEGRA GRANDE | F18: 65777220 | G18: MAGDA TAFUR | H18: 25000
A19: 46178 | B19: 65777220 | C19: MAGDA TAFUR | D19: COMPRAS | E19: COMPRA DE ALUMINIO GERENCIA | F19: 901812925-0 | G19: COMERCIALIZADORA A Y F | H19: 40500
A20: 46178 | B20: 1005838694 | C20: ANGELA TRIVIÑO | D20: CONTABILIDAD | E20: CERTIFICADO DE CAMARA Y COMERCIO | F20: 890700622-4 | G20: CAMARA Y COMERCIO DE IBAGUE | H20: 12100
H23: =SUM(H12:H22) -> 203400
H25: =H10-H23 -> -1828829.4
B28: 110580597 | C28: WILIAN FELIPE | D28: PLANEACION
B29: 65777220 | C29: MAGDA TAFUR | D29: COMPRAS
B30: 65737477 | C30: SANDRA GALLEGO | D30: RECEPCION
B31: 14106438 | C31: DIEGO RADA | D31: CONTRATACION
B32: 5939109 | C32: MIRVEAN HERNANDEZ | D32: LOGISTICA
B33: 13239826 | C33: EDISON LEAL | D33: RECEPCION
B34: 65762110 | C34: SANDRA BONILLA | D34: CONTRATACION
B35: 1032372158 | C35: HAROLD FERIAS | D35: LOGISTICA
B36: 1110511708 | C36: FABIAN PEREZ | D36: INGENIERO
B37: 1110546445 | C37: MARIO GARCIA | D37: LOSGISTICA
B38: 1006123077 | C38: JOHAN GARZON | D38: AUXILIAR L.
B39: 14236999 | C39: JAIRO ARIAS | D39: PRODUCCION
... B44: 1007832826 | C44: SEBASTIAN GONGORA | D44: PLANIACION
B45: 800185306-4 | C45: ENVIA
B46: 1110546445 | C46: MARIO GARCIA | D46: LOSGISTICA
B47: 1005717607 | C47: JIMY GUTIERREZ | D47: LOSGISTICA
B48: 14243741 | C48: JUAN HORTA | D48: PRODUCCION
B49: 1110442630 | C49: JERSSON OROZCO | D49: LOGISTICA
B50: 900276962-1 | C50: D1 SAS
B51: 800251569 | C51: INTERRAPIDISOMO
B52: 1006122533 | C52: LAURA MARIN | D52: COMUNICADORA

Sheet MAYO 08 2026  
D1: CAJA MENOR
A7: FECHA | B7: CEDULA(NIT) | C7: NOMBRE | D7: FUNCIONARIO | E7: DESCRIPCIÓN O DETALLE | F7: NIT | G7: PROVEEDOR
H10: ='MAYO 07 2026 '!H25 -> -1828829.4
A12: 46239 | B12: 1006123077 | C12: JOHAN GARZON | D12: AUXILIAR L. | E12: TRANSPORTE AGUA VENECIA | F12: 1006123077 | G12: JOHAN GARZON | H12: 14100
A13: 46239 | B13: 13239826 | C13: EDISON LEAL | D13: RECEPCION | E13: ENVIO PQT A ESPINAL | F13: 13239826 | G13: EDISON LEAL | H13: 14000
A14: 46239 | B14: 13239826 | C14: EDISON LEAL | D14: RECEPCION | E14: PARQUEADERO MENSAJERO | F14: 14209150-7 | G14: PARQUEADERO MAFEGILI | H14: 1900
A15: 46239 | B15: 13239826 | C15: EDISON LEAL | D15: RECEPCION | E15: PARQUEADERO MENSAJERO | F15: 71643223-3 | G15: PARQUEADERO JAIMAR | H15: 1900
A16: 46239 | B16: 65737477 | C16: SANDRA GALLEGO | D16: RECEPCION | E16: EVENTO UT | F16: 901370428-3 | G16: SUPERMERCADO MERCACENTRO | H16: 14400
H23: =SUM(H12:H22) -> 46300
H25: =H10-H23 -> -1875129.4
B28: 110580597 | C28: WILIAN FELIPE | D28: PLANEACION
B29: 65777220 | C29: MAGDA TAFUR | D29: COMPRAS
B30: 65737477 | C30: SANDRA GALLEGO | D30: RECEPCION
B31: 14106438 | C31: DIEGO RADA | D31: CONTRATACION
B32: 5939109 | C32: MIRVEAN HERNANDEZ | D32: LOGISTICA
B33: 13239826 | C33: EDISON LEAL | D33: RECEPCION
B34: 65762110 | C34: SANDRA BONILLA | D34: CONTRATACION
B35: 1032372158 | C35: HAROLD FERIAS | D35: LOGISTICA
B36: 1110511708 | C36: FABIAN PEREZ | D36: INGENIERO
B37: 1110546445 | C37: MARIO GARCIA | D37: LOSGISTICA
B38: 1006123077 | C38: JOHAN GARZON | D38: AUXILIAR L.
B39: 14236999 | C39: JAIRO ARIAS | D39: PRODUCCION
... B44: 1007832826 | C44: SEBASTIAN GONGORA | D44: PLANIACION
B45: 800185306-4 | C45: ENVIA
B46: 1110546445 | C46: MARIO GARCIA | D46: LOSGISTICA
B47: 1005717607 | C47: JIMY GUTIERREZ | D47: LOSGISTICA
B48: 14243741 | C48: JUAN HORTA | D48: PRODUCCION
B49: 1110442630 | C49: JERSSON OROZCO | D49: LOGISTICA
B50: 900276962-1 | C50: D1 SAS
B51: 800251569 | C51: INTERRAPIDISOMO
B52: 1006122533 | C52: LAURA MARIN | D52: COMUNICADORA

Sheet MAYO 11 2026  
D1: CAJA MENOR
A7: FECHA | B7: CEDULA(NIT) | C7: NOMBRE | D7: FUNCIONARIO | E7: DESCRIPCIÓN O DETALLE | F7: NIT | G7: PROVEEDOR
H10: ='MAYO 09 2026 '!H25 -> -1970729.4
A12: 46331 | B12: 65737477 | C12: SANDRA GALLEGO | D12: RECEPCION | E12: TRANSPORTE FUENTE REAL MEDICADIZ- MEDICADIZ FUENTE REAL | F12: 65737477 | G12: SANDRA GALLEGO | H12: 38800
A13: 46331 | B13: 65737477 | C13: SANDRA GALLEGO | D13: RECEPCION | E13: TAXI MEDICADIZ - LEON | F13: 65737477 | G13: SANDRA GALLEGO | H13: 18700
A14: 46331 | B14: 65737477 | C14: SANDRA GALLEGO | D14: RECEPCION | E14: ALMUERZO ADMINISTRATIVA | F14: 65737477 | G14: SANDRA GALLEGO | H14: 39000
A15: 46331 | B15: 11105944298 | C15: CARLOS CASTRO | D15: LOGISTICO | E15: TAXIS LOGISTICO | F15: 11105944298 | G15: CARLOS CASTRO | H15: 36000
A16: 46331 | B16: 11105944298 | C16: CARLOS CASTRO | D16: LOGISTICO | E16: TAXIS LOGISTICO | F16: 11105944298 | G16: CARLOS CASTRO | H16: 36000
A17: 46331 | B17: 11105944298 | C17: CARLOS CASTRO | D17: LOGISTICO | E17: TAXIS LOGISTICO | F17: 11105944298 | G17: CARLOS CASTRO | H17: 24000
A18: 46331 | B18: 1234638696 | C18: GIOUANNI HURTADO | D18: LOGISTICA | E18: TRANSPORTE | F18: 1234638696 | G18: GIOUANNI HURTADO | H18: 42000
A19: 46331 | B19: 1110472296 | C19: RICARDO VASCO | D19: PRODUCCION IN | E19: TRANSPORTE COMPRA REPUESTO MONTA CARGA | F19: 1110472296 | G19: RICARDO VASCO | H19: 10000
A20: 46331 | B20: 1110472296 | C20: RICARDO VASCO | D20: PRODUCCION IN | E20: COMPRAS PLATINAS MONTA CARGA | F20: 17052346-8 | G20: DEPOSITO PINZON | H20: 25000
A21: 46331 | B21: 13239826 | C21: EDISON LEAL | D21: RECEPCION | E21: PARQUEADERO MENSAJERO | F21: 901153147-9 | G21: COMPLEJO MEDICO LA SAMARIA | H21: 1900
H23: =SUM(H12:H22) -> 271400
H25: =H10-H23 -> -2242129.4
B28: 110580597 | C28: WILIAN FELIPE | D28: PLANEACION
B29: 65777220 | C29: MAGDA TAFUR | D29: COMPRAS
B30: 65737477 | C30: SANDRA GALLEGO | D30: RECEPCION
B31: 14106438 | C31: DIEGO RADA | D31: CONTRATACION
B32: 5939109 | C32: MIRVEAN HERNANDEZ | D32: LOGISTICA
B33: 13239826 | C33: EDISON LEAL | D33: RECEPCION
B34: 65762110 | C34: SANDRA BONILLA | D34: CONTRATACION
B35: 1032372158 | C35: HAROLD FERIAS | D35: LOGISTICA
B36: 1110511708 | C36: FABIAN PEREZ | D36: INGENIERO
B37: 1110546445 | C37: MARIO GARCIA | D37: LOSGISTICA
B38: 1006123077 | C38: JOHAN GARZON | D38: AUXILIAR L.
B39: 14236999 | C39: JAIRO ARIAS | D39: PRODUCCION
... B44: 1007832826 | C44: SEBASTIAN GONGORA | D44: PLANIACION
B45: 800185306-4 | C45: ENVIA
B46: 1110546445 | C46: MARIO GARCIA | D46: LOSGISTICA
B47: 1005717607 | C47: JIMY GUTIERREZ | D47: LOSGISTICA
B48: 14243741 | C48: JUAN HORTA | D48: PRODUCCION
B49: 1110442630 | C49: JERSSON OROZCO | D49: LOGISTICA
B50: 900276962-1 | C50: D1 SAS
B51: 800251569 | C51: INTERRAPIDISOMO
B52: 1006122533 | C52: LAURA MARIN | D52: COMUNICADORA

Sheet MAYO 09 2026 
D1: CAJA MENOR
A7: FECHA | B7: CEDULA(NIT) | C7: NOMBRE | D7: FUNCIONARIO | E7: DESCRIPCIÓN O DETALLE | F7: NIT | G7: PROVEEDOR
H10: ='MAYO 08 2026 '!H25 -> -1875129.4
A12: 46270 | B12: 13239826 | C12: EDISON LEAL | D12: RECEPCION | E12: ALMUERZO SABADO | F12: 13239826 | G12: EDISON LEAL | H12: 14000
A13: 46270 | B13: 13239826 | C13: EDISON LEAL | D13: RECEPCION | E13: TRANSPORTE AGUAS PISTA MOTOCROSS | F13: 13239826 | G13: EDISON LEAL | H13: 30000
A14: 46270 | B14: 1234638696 | C14: GIOUANNI HURTADO | D14: LOGISTICA | E14: COMPRA DE INSTACREM | F14: 901768321-4 | G14: ARCINIEGAS ASOCIADOS | H14: 17100
A15: 46270 | B15: 65737477 | C15: SANDRA GALLEGO | D15: RECEPCION | E15: COMPRA DE MANZANAS REFRIJERIO | F15: 901549003-8 | G15: FRUVER LA GRANJA | H15: 34500
H23: =SUM(H12:H22) -> 95600
H25: =H10-H23 -> -1970729.4
B28: 110580597 | C28: WILIAN FELIPE | D28: PLANEACION
B29: 65777220 | C29: MAGDA TAFUR | D29: COMPRAS
B30: 65737477 | C30: SANDRA GALLEGO | D30: RECEPCION
B31: 14106438 | C31: DIEGO RADA | D31: CONTRATACION
B32: 5939109 | C32: MIRVEAN HERNANDEZ | D32: LOGISTICA
B33: 13239826 | C33: EDISON LEAL | D33: RECEPCION
B34: 65762110 | C34: SANDRA BONILLA | D34: CONTRATACION
B35: 1032372158 | C35: HAROLD FERIAS | D35: LOGISTICA
B36: 1110511708 | C36: FABIAN PEREZ | D36: INGENIERO
B37: 1110546445 | C37: MARIO GARCIA | D37: LOSGISTICA
B38: 1006123077 | C38: JOHAN GARZON | D38: AUXILIAR L.
B39: 14236999 | C39: JAIRO ARIAS | D39: PRODUCCION
... B44: 1007832826 | C44: SEBASTIAN GONGORA | D44: PLANIACION
B45: 800185306-4 | C45: ENVIA
B46: 1110546445 | C46: MARIO GARCIA | D46: LOSGISTICA
B47: 1005717607 | C47: JIMY GUTIERREZ | D47: LOSGISTICA
B48: 14243741 | C48: JUAN HORTA | D48: PRODUCCION
B49: 1110442630 | C49: JERSSON OROZCO | D49: LOGISTICA
B50: 900276962-1 | C50: D1 SAS
B51: 800251569 | C51: INTERRAPIDISOMO
B52: 1006122533 | C52: LAURA MARIN | D52: COMUNICADORA

Sheet MAYO 12 2026 
D1: CAJA MENOR
A7: FECHA | B7: CEDULA(NIT) | C7: NOMBRE | D7: FUNCIONARIO | E7: DESCRIPCIÓN O DETALLE | F7: NIT | G7: PROVEEDOR
H10: ='MAYO 11 2026 '!H25 -> -2242129.4
A12: 46361 | B12: 5927717 | C12: ERWIN SANTIAGO | D12: LOGISTICO | E12: TRANSPORTE LOGISTICO | F12: 5927717 | G12: ERWIN SANTIAGO | H12: 28000
A13: 46361 | B13: 5927717 | C13: ERWIN SANTIAGO | D13: LOGISTICO | E13: TRANSPORTE LOGISTICO | F13: 5927717 | G13: ERWIN SANTIAGO | H13: 28000
A14: 46361 | B14: 5927717 | C14: ERWIN SANTIAGO | D14: LOGISTICO | E14: TRANSPORTE LOGISTICO | F14: 5927717 | G14: ERWIN SANTIAGO | H14: 26000
A15: 46361 | B15: 65762110 | C15: SANDRA BONILLA | D15: CONTRATACION | E15: TRANSPORTE | F15: 65762110 | G15: SANDRA BONILLA | H15: 10000
A16: 46361 | B16: 1000775862 | C16: YOJHAN RATIVA | D16: LOGISTICA | E16: TRANSPORTE LOGISTICO | F16: 1000775862 | G16: YOJHAN RATIVA | H16: 32000
A17: 46361 | B17: 1000775862 | C17: YOJHAN RATIVA | D17: LOGISTICA | E17: TRANSPORTE LOGISTICO | F17: 1000775862 | G17: YOJHAN RATIVA | H17: 32000
A18: 46361 | B18: 65737477 | C18: SANDRA GALLEGO | D18: RECEPCION | E18: DOMICILIO HORNEADOS | F18: 65737477 | G18: SANDRA GALLEGO | H18: 7000
A19: 46361 | B19: 1110472296 | C19: RICARDO VASCO | D19: PRODUCCION IN | E19: REPUESTO PARA MONTA CARGUERO | F19: 1110472296 | G19: RICARDO VASCO | H19: 20000
A20: 46361 | B20: 65737477 | C20: SANDRA GALLEGO | D20: RECEPCION | E20: SERVICIO DE TRANSPORTE | F20: 12111653 | G20: JOSE MANUEL NIÑO PINILL | H20: 30000
A21: 46361 | B21: 65737477 | C21: SANDRA GALLEGO | D21: RECEPCION | E21: AZUCAR CAFETERIA | F21: 901768321-4 | G21: ARCINIEGAS ASOCIADOS | H21: 17410
H23: =SUM(H12:H22) -> 230410
H25: =H10-H23 -> -2472539.4
B28: 110580597 | C28: WILIAN FELIPE | D28: PLANEACION
B29: 65777220 | C29: MAGDA TAFUR | D29: COMPRAS
B30: 65737477 | C30: SANDRA GALLEGO | D30: RECEPCION
B31: 14106438 | C31: DIEGO RADA | D31: CONTRATACION
B32: 5939109 | C32: MIRVEAN HERNANDEZ | D32: LOGISTICA
B33: 13239826 | C33: EDISON LEAL | D33: RECEPCION
B34: 65762110 | C34: SANDRA BONILLA | D34: CONTRATACION
B35: 1032372158 | C35: HAROLD FERIAS | D35: LOGISTICA
B36: 1110511708 | C36: FABIAN PEREZ | D36: INGENIERO
B37: 1110546445 | C37: MARIO GARCIA | D37: LOSGISTICA
B38: 1006123077 | C38: JOHAN GARZON | D38: AUXILIAR L.
B39: 14236999 | C39: JAIRO ARIAS | D39: PRODUCCION
... B44: 1007832826 | C44: SEBASTIAN GONGORA | D44: PLANIACION
B45: 800185306-4 | C45: ENVIA
B46: 1110546445 | C46: MARIO GARCIA | D46: LOSGISTICA
B47: 1005717607 | C47: JIMY GUTIERREZ | D47: LOSGISTICA
B48: 14243741 | C48: JUAN HORTA | D48: PRODUCCION
B49: 1110442630 | C49: JERSSON OROZCO | D49: LOGISTICA
B50: 900276962-1 | C50: D1 SAS
B51: 800251569 | C51: INTERRAPIDISOMO
B52: 1006122533 | C52: LAURA MARIN | D52: COMUNICADORA

Sheet MAYO 13 2026 
D1: CAJA MENOR
A7: FECHA | B7: CEDULA(NIT) | C7: NOMBRE | D7: FUNCIONARIO | E7: DESCRIPCIÓN O DETALLE | F7: NIT | G7: PROVEEDOR
H10: ='MAYO 12 2026 '!H25 -> -2472539.4
A12: 5/13/2026 | B12: 1110442630 | C12: JERSSON OROZCO | D12: LOGISTICA | E12: TRANSPORTE LOGISTICO | F12: 1110442630 | G12: JERSSON OROZCO | H12: 48000
A13: 5/13/2026 | B13: 1110442630 | C13: JERSSON OROZCO | D13: LOGISTICA | E13: TRANSPORTE LOGISTICO | F13: 1110442630 | G13: JERSSON OROZCO | H13: 18000
A14: 5/13/2026 | B14: 65777220 | C14: MAGDA TAFUR | D14: COMPRAS | E14: TRANSPORTE EVENTO GOBERNACION | F14: 65777220 | G14: MAGDA TAFUR | H14: 40000
A15: 5/13/2026 | B15: 65737477 | C15: SANDRA GALLEGO | D15: RECEPCION | E15: REPUESTOS PARA PUERTA GERENCIA | F15: 65737477 | G15: SANDRA GALLEGO | H15: 26000
A16: 5/13/2026 | B16: 65737477 | C16: SANDRA GALLEGO | D16: RECEPCION | E16: REPUESTOS PARA PUERTA GERENCIA | F16: 65737477 | G16: SANDRA GALLEGO | H16: 26000
A17: 5/13/2026 | B17: 65762110 | C17: SANDRA BONILLA | D17: CONTRATACION | E17: MANILLAS FESTIVAL FOLCLORICO | F17: 800251569 | G17: INTER RAPIDISIMO | H17: 43700
A18: 5/13/2026 | B18: 65777220 | C18: MAGDA TAFUR | D18: COMPRAS | E18: COMPRA DE PLATOS LOGISTICA | F18: 90181295-0 | G18: COMERCIALIZADORA A Y F | H18: 31500
A19: 5/13/2026 | B19: 13239826 | C19: EDISON LEAL | D19: RECEPCION | E19: PARQUEADERO MENSAJERO | F19: 901312036-2 | G19: PARQUEADERO M-TREINTA | H19: 2100
A20: 5/13/2026 | B20: 65737477 | C20: SANDRA GALLEGO | D20: RECEPCION | E20: CEPILLO PARA SANITARIO | F20: 8909006089 | G20: CL SI FA SI DI NA | H20: 39000
A21: 5/13/2026 | B21: 65777220 | C21: MAGDA TAFUR | D21: COMPRAS | E21: ARREGLO PERCOLADORA | F21: 65777220 | G21: MAGDA TAFUR | H21: 10000
H23: =SUM(H12:H22) -> 284300
H25: =H10-H23 -> -2756839.4
B28: 110580597 | C28: WILIAN FELIPE | D28: PLANEACION
B29: 65777220 | C29: MAGDA TAFUR | D29: COMPRAS
B30: 65737477 | C30: SANDRA GALLEGO | D30: RECEPCION
B31: 14106438 | C31: DIEGO RADA | D31: CONTRATACION
B32: 5939109 | C32: MIRVEAN HERNANDEZ | D32: LOGISTICA
B33: 13239826 | C33: EDISON LEAL | D33: RECEPCION
B34: 65762110 | C34: SANDRA BONILLA | D34: CONTRATACION
B35: 1032372158 | C35: HAROLD FERIAS | D35: LOGISTICA
B36: 1110511708 | C36: FABIAN PEREZ | D36: INGENIERO
B37: 1110546445 | C37: MARIO GARCIA | D37: LOSGISTICA
B38: 1006123077 | C38: JOHAN GARZON | D38: AUXILIAR L.
B39: 14236999 | C39: JAIRO ARIAS | D39: PRODUCCION
... B44: 1007832826 | C44: SEBASTIAN GONGORA | D44: PLANIACION
B45: 800185306-4 | C45: ENVIA
B46: 1110546445 | C46: MARIO GARCIA | D46: LOSGISTICA
B47: 1005717607 | C47: JIMY GUTIERREZ | D47: LOSGISTICA
B48: 14243741 | C48: JUAN HORTA | D48: PRODUCCION
B49: 1110442630 | C49: JERSSON OROZCO | D49: LOGISTICA
B50: 900276962-1 | C50: D1 SAS
B51: 800251569 | C51: INTERRAPIDISOMO
B52: 1006122533 | C52: LAURA MARIN | D52: COMUNICADORA

Sheet MAYO 14 2026 
D1: CAJA MENOR
A7: FECHA | B7: CEDULA(NIT) | C7: NOMBRE | D7: FUNCIONARIO | E7: DESCRIPCIÓN O DETALLE | F7: NIT | G7: PROVEEDOR
H10: ='MAYO 13 2026 '!H25 -> -2756839.4
A12: 5/14/2026 | B12: 13239826 | C12: EDISON LEAL | D12: RECEPCION | E12: ENVIO PQT GIRARDOT | F12: 13239826 | G12: EDISON LEAL | H12: 17000
A13: 5/14/2026 | B13: 65762110 | C13: SANDRA BONILLA | D13: CONTRATACION | E13: ALMUERZO JUEVES | F13: 65762110 | G13: SANDRA BONILLA | H13: 14000
A14: 5/14/2026 | B14: 65737477 | C14: SANDRA GALLEGO | D14: RECEPCION | E14: TAXIS LEON - MEDICADIZ - MEDICADIZ - FUENTE REAL | F14: 65737477 | G14: SANDRA GALLEGO | H14: 34200
A15: 5/14/2026 | B15: 1110472296 | C15: RICARDO VASCO | D15: PRODUCCION IN | E15: TRANSPORTE COMPRAS MONTACARGA | F15: 1110472296 | G15: RICARDO VASCO | H15: 10000
A16: 5/14/2026 | B16: 65777220 | C16: MAGDA TAFUR | D16: COMPRAS | E16: COMPRA DE LOZA LOGISTICA | F16: 901812925-0 | G16: COMERCIALIZADORA A Y F | H16: 10500
A17: 5/14/2026 | B17: 13239826 | C17: EDISON LEAL | D17: RECEPCION | E17: PARQUEADERO MENSAJERO | F17: 901153147-9 | G17: COMPLEJO MEDICO LA SAMARIA | H17: 1900
A18: 5/14/2026 | B18: 65737477 | C18: SANDRA GALLEGO | D18: RECEPCION | E18: PILAS GERENCIA | F18: 901370428-3 | G18: SUPERMERCADO MERCACENTRO | H18: 2800
A19: 5/14/2026 | B19: 1110472296 | C19: RICARDO VASCO | D19: PRODUCCION IN | E19: COMPRA REPUESTO PARA CARGUERO | F19: 900870033 | G19: LA ESPAÑOLA | H19: 41400
H23: =SUM(H12:H22) -> 131800
H25: =H10-H23 -> -2888639.4
B28: 110580597 | C28: WILIAN FELIPE | D28: PLANEACION
B29: 65777220 | C29: MAGDA TAFUR | D29: COMPRAS
B30: 65737477 | C30: SANDRA GALLEGO | D30: RECEPCION
B31: 14106438 | C31: DIEGO RADA | D31: CONTRATACION
B32: 5939109 | C32: MIRVEAN HERNANDEZ | D32: LOGISTICA
B33: 13239826 | C33: EDISON LEAL | D33: RECEPCION
B34: 65762110 | C34: SANDRA BONILLA | D34: CONTRATACION
B35: 1032372158 | C35: HAROLD FERIAS | D35: LOGISTICA
B36: 1110511708 | C36: FABIAN PEREZ | D36: INGENIERO
B37: 1110546445 | C37: MARIO GARCIA | D37: LOSGISTICA
B38: 1006123077 | C38: JOHAN GARZON | D38: AUXILIAR L.
B39: 14236999 | C39: JAIRO ARIAS | D39: PRODUCCION
... B44: 1007832826 | C44: SEBASTIAN GONGORA | D44: PLANIACION
B45: 800185306-4 | C45: ENVIA
B46: 1110546445 | C46: MARIO GARCIA | D46: LOSGISTICA
B47: 1005717607 | C47: JIMY GUTIERREZ | D47: LOSGISTICA
B48: 14243741 | C48: JUAN HORTA | D48: PRODUCCION
B49: 1110442630 | C49: JERSSON OROZCO | D49: LOGISTICA
B50: 900276962-1 | C50: D1 SAS
B51: 800251569 | C51: INTERRAPIDISOMO
B52: 1006122533 | C52: LAURA MARIN | D52: COMUNICADORA

Sheet MAYO 15 2026  
D1: CAJA MENOR
A7: FECHA | B7: CEDULA(NIT) | C7: NOMBRE | D7: FUNCIONARIO | E7: DESCRIPCIÓN O DETALLE | F7: NIT | G7: PROVEEDOR
H10: ='MAYO 14 2026 '!H25 -> -2888639.4
A12: 5/15/2026 | B12: 111046289 | C12: JHON CARDENAS | D12: LOGISTICA | E12: TRANSPORTE IGUAIMA | F12: 111046289 | G12: JHON CARDENAS | H12: 12000
A13: 5/15/2026 | B13: 28542010 | C13: ADRIANA NARVAEZ | D13: DIRECCION DE COSTOS | E13: ALMUERZO CON ALEJANDRO DE INDEPORTES | F13: 28542010 | G13: ADRIANA NARVAEZ | H13: 31000
A14: 5/15/2026 | B14: 65777220 | C14: MAGDA TAFUR | D14: COMPRAS | E14: TRANSPORTE LLEVAR VARIOS A LA GOBERNACION | F14: 65777220 | G14: MAGDA TAFUR | H14: 7500
A15: 5/15/2026 | B15: 13239826 | C15: EDISON LEAL | D15: RECEPCION | E15: TRANSPORTE 9 CAJAS SYSCAFE | F15: 13239826 | G15: EDISON LEAL | H15: 22000
A16: 5/15/2026 | B16: 13239826 | C16: EDISON LEAL | D16: RECEPCION | E16: PARQUEADERO MENSAJERO | F16: 38225162 | G16: PARQUEADERO LA TERTULIA | H16: 900
A17: 5/15/2026 | B17: 65737477 | C17: SANDRA GALLEGO | D17: RECEPCION | E17: COLADORES DE LA GRECA | F17: 901812925-0 | G17: COMERCIALIZADORA A Y F | H17: 13000
A18: 5/15/2026 | B18: 65737477 | C18: SANDRA GALLEGO | D18: RECEPCION | E18: CARGADOR CELULAR RECEPCION | F18: 72305756-1 | G18: JORGE ARMANDO GARCIA | H18: 30000
A19: 5/15/2026 | B19: 65737477 | C19: SANDRA GALLEGO | D19: RECEPCION | E19: PILAS AAA LOGISTICA | F19: 1110469628-9 | G19: AUTOSERVIR | H19: 2600
A20: 5/15/2026 | B20: 65737477 | C20: SANDRA GALLEGO | D20: RECEPCION | E20: COMPRAS ESPONJAS LOGISTICA LAVAR BAÑOS | F20: 1110469628-9 | G20: AUTOSERVIR | H20: 3000
A21: 5/15/2026 | B21: 65737477 | C21: SANDRA GALLEGO | D21: RECEPCION | E21: RECIBO ALCANOS EDIFICIO LEON | F21: 891101577-4 | G21: ALCANOS DE COLOMBIA | H21: 5440
H23: =SUM(H12:H22) -> 127440
H25: =H10-H23 -> -3016079.4
B28: 110580597 | C28: WILIAN FELIPE | D28: PLANEACION
B29: 65777220 | C29: MAGDA TAFUR | D29: COMPRAS
B30: 65737477 | C30: SANDRA GALLEGO | D30: RECEPCION
B31: 14106438 | C31: DIEGO RADA | D31: CONTRATACION
B32: 5939109 | C32: MIRVEAN HERNANDEZ | D32: LOGISTICA
B33: 13239826 | C33: EDISON LEAL | D33: RECEPCION
B34: 65762110 | C34: SANDRA BONILLA | D34: CONTRATACION
B35: 1032372158 | C35: HAROLD FERIAS | D35: LOGISTICA
B36: 1110511708 | C36: FABIAN PEREZ | D36: INGENIERO
B37: 1110546445 | C37: MARIO GARCIA | D37: LOSGISTICA
B38: 1006123077 | C38: JOHAN GARZON | D38: AUXILIAR L.
B39: 14236999 | C39: JAIRO ARIAS | D39: PRODUCCION
... B44: 1007832826 | C44: SEBASTIAN GONGORA | D44: PLANIACION
B45: 800185306-4 | C45: ENVIA
B46: 1110546445 | C46: MARIO GARCIA | D46: LOSGISTICA
B47: 1005717607 | C47: JIMY GUTIERREZ | D47: LOSGISTICA
B48: 14243741 | C48: JUAN HORTA | D48: PRODUCCION
B49: 1110442630 | C49: JERSSON OROZCO | D49: LOGISTICA
B50: 900276962-1 | C50: D1 SAS
B51: 800251569 | C51: INTERRAPIDISOMO
B52: 1006122533 | C52: LAURA MARIN | D52: COMUNICADORA
B53: 111046289 | C53: JHON CARDENAS | D53: LOGISTICA
B54: 28542010 | C54: ADRIANA NARVAEZ | D54: DIRECCION DE COSTOS

Sheet MAYO 16 2026
D1: CAJA MENOR
A7: FECHA | B7: CEDULA(NIT) | C7: NOMBRE | D7: FUNCIONARIO | E7: DESCRIPCIÓN O DETALLE | F7: NIT | G7: PROVEEDOR
H10: ='MAYO 15 2026 '!H25 -> -3016079.4
A12: 5/16/2026 | B12: 1110496867 | C12: LUISA GONZALES | D12: AUX. CONTABLE | E12: ALMUERZOS CONTABILIDAD | F12: 1110496867 | G12: LUISA GONZALES | H12: 27500
A13: 5/16/2026 | B13: 1110496867 | C13: LUISA GONZALES | D13: AUX. CONTABLE | E13: ALMUERZOS CONTABILIDAD | F13: 1110496867 | G13: LUISA GONZALES | H13: 27500
A14: 5/16/2026 | B14: 13239826 | C14: EDISON LEAL | D14: RECEPCION | E14: LLEVAR CAJAS VASCONIA - AGENDAS | F14: 13239826 | G14: EDISON LEAL | H14: 20000
A15: 5/16/2026 | B15: 65737477 | C15: SANDRA GALLEGO | D15: RECEPCION | E15: MEDICAMENTO GERENCIA | F15: 830011670-3 | G15: COOPERATIVA MULTIACTIVA DE SERVICIOS | H15: 38700
H23: =SUM(H12:H22) -> 113700
H25: =H10-H23 -> -3129779.4
B28: 110580597 | C28: WILIAN FELIPE | D28: PLANEACION
B29: 65777220 | C29: MAGDA TAFUR | D29: COMPRAS
B30: 65737477 | C30: SANDRA GALLEGO | D30: RECEPCION
B31: 14106438 | C31: DIEGO RADA | D31: CONTRATACION
B32: 5939109 | C32: MIRVEAN HERNANDEZ | D32: LOGISTICA
B33: 13239826 | C33: EDISON LEAL | D33: RECEPCION
B34: 65762110 | C34: SANDRA BONILLA | D34: CONTRATACION
B35: 1032372158 | C35: HAROLD FERIAS | D35: LOGISTICA
B36: 1110511708 | C36: FABIAN PEREZ | D36: INGENIERO
B37: 1110546445 | C37: MARIO GARCIA | D37: LOSGISTICA
B38: 1006123077 | C38: JOHAN GARZON | D38: AUXILIAR L.
B39: 14236999 | C39: JAIRO ARIAS | D39: PRODUCCION
... B44: 1007832826 | C44: SEBASTIAN GONGORA | D44: PLANIACION
B45: 800185306-4 | C45: ENVIA
B46: 1110546445 | C46: MARIO GARCIA | D46: LOSGISTICA
B47: 1005717607 | C47: JIMY GUTIERREZ | D47: LOSGISTICA
B48: 14243741 | C48: JUAN HORTA | D48: PRODUCCION
B49: 1110442630 | C49: JERSSON OROZCO | D49: LOGISTICA
B50: 900276962-1 | C50: D1 SAS
B51: 800251569 | C51: INTERRAPIDISOMO
B52: 1006122533 | C52: LAURA MARIN | D52: COMUNICADORA
B53: 111046289 | C53: JHON CARDENAS | D53: LOGISTICA
B54: 28542010 | C54: ADRIANA NARVAEZ | D54: DIRECCION DE COSTOS

Sheet MAYO 19 2026 
D1: CAJA MENOR
A7: FECHA | B7: CEDULA(NIT) | C7: NOMBRE | D7: FUNCIONARIO | E7: DESCRIPCIÓN O DETALLE | F7: NIT | G7: PROVEEDOR
H10: ='MAYO 16 2026'!H25 -> -3129779.4
A12: 5/19/2026 | B12: 13239826 | C12: EDISON LEAL | D12: RECEPCION | E12: TRANSPORTE MENSAJERO | F12: 13239826 | G12: EDISON LEAL | H12: 9500
A13: 5/19/2026 | B13: 1110486217 | C13: ALEXANDER VARGAS | D13: DOMICILIARIO | E13: DOMICILIO DON LAVADORAS | F13: 1110486217 | G13: ALEXANDER VARGAS | H13: 8000
A14: 5/19/2026 | B14: 65737477 | C14: SANDRA GALLEGO | D14: RECEPCION | E14: TRANSPORTE DE AGENDAS PRODUCCION | F14: 65737477 | G14: SANDRA GALLEGO | H14: 20000
A15: 5/19/2026 | B15: 65777220 | C15: MAGDA TAFUR | D15: COMPRAS | E15: COMPRA PORTA LAPICEROS GERENCIA | F15: 65777220 | G15: MAGDA TAFUR | H15: 14000
A16: 5/19/2026 | B16: 1110580407 | C16: JEFERSON AVENDAÑO | D16: DOMICILIARIO | E16: DOMICILIO DELIRIOS Y EL RODAMIENTO | F16: 1110580407 | G16: JEFERSON AVENDAÑO | H16: 13000
A17: 5/19/2026 | B17: 65737477 | C17: SANDRA GALLEGO | D17: RECEPCION | E17: TRANSPORTE VARIOS: LLEVAR TROPEZONES | F17: 12111653 | G17: JOSE MANUEL NIÑO PINILLA | H17: 30000
A18: 5/19/2026 | B18: 65777220 | C18: MAGDA TAFUR | D18: COMPRAS | E18: COMPRA TAMALES EVENTOS GOBERNACION | F18: 1024461420 | G18: TAMALES AUGUSTO | H18: 48000
A19: 5/19/2026 | B19: 65777220 | C19: MAGDA TAFUR | D19: COMPRAS | E19: COMPRA U.T | F19: 900241288-2 | G19: PAPELERIA LA COMUNA | H19: 15500
A20: 5/19/2026 | B20: 13239826 | C20: EDISON LEAL | D20: RECEPCION | E20: PARQUEADERO MENSAJERO | F20: 901312036-2 | G20: PARQUEADERO M-TREINTA | H20: 2100
A21: 5/19/2026 | B21: 65777220 | C21: MAGDA TAFUR | D21: COMPRAS | E21: COMPRA PAN EVENTO GOBERNACION | F21: 901006707-4 | G21: LA MORATA | H21: 12000
A22: 5/19/2026 | B22: 13239826 | C22: EDISON LEAL | D22: RECEPCION | E22: PARQUEADERO MENSAJERO | F22: 901153147-9 | G22: COMPLEJO MEDICO LA SAMARIA | H22: 1900
A23: 5/19/2026 | B23: 65777220 | C23: MAGDA TAFUR | D23: COMPRAS | E23: COMPRA EVENTO GOBERNACION | F23: 830037946-3 | G23: PANAMERICANA | H23: 25000
H25: =SUM(H12:H24) -> 199000
H27: =H10-H25 -> -3328779.4
B30: 110580597 | C30: WILIAN FELIPE | D30: PLANEACION
B31: 65777220 | C31: MAGDA TAFUR | D31: COMPRAS
B32: 65737477 | C32: SANDRA GALLEGO | D32: RECEPCION
B33: 14106438 | C33: DIEGO RADA | D33: CONTRATACION
B34: 5939109 | C34: MIRVEAN HERNANDEZ | D34: LOGISTICA
B35: 13239826 | C35: EDISON LEAL | D35: RECEPCION
B36: 65762110 | C36: SANDRA BONILLA | D36: CONTRATACION
B37: 1032372158 | C37: HAROLD FERIAS | D37: LOGISTICA
B38: 1110511708 | C38: FABIAN PEREZ | D38: INGENIERO
B39: 1110546445 | C39: MARIO GARCIA | D39: LOSGISTICA
B40: 1006123077 | C40: JOHAN GARZON | D40: AUXILIAR L.
B41: 14236999 | C41: JAIRO ARIAS | D41: PRODUCCION
... B46: 1007832826 | C46: SEBASTIAN GONGORA | D46: PLANIACION
B47: 800185306-4 | C47: ENVIA
B48: 1110546445 | C48: MARIO GARCIA | D48: LOSGISTICA
B49: 1005717607 | C49: JIMY GUTIERREZ | D49: LOSGISTICA
B50: 14243741 | C50: JUAN HORTA | D50: PRODUCCION
B51: 1110442630 | C51: JERSSON OROZCO | D51: LOGISTICA
B52: 900276962-1 | C52: D1 SAS
B53: 800251569 | C53: INTERRAPIDISOMO
B54: 1006122533 | C54: LAURA MARIN | D54: COMUNICADORA
B55: 111046289 | C55: JHON CARDENAS | D55: LOGISTICA
B56: 28542010 | C56: ADRIANA NARVAEZ | D56: DIRECCION DE COSTOS

Sheet MAYO 20 2026  
D1: CAJA MENOR
A7: FECHA | B7: CEDULA(NIT) | C7: NOMBRE | D7: FUNCIONARIO | E7: DESCRIPCIÓN O DETALLE | F7: NIT | G7: PROVEEDOR
H10: ='MAYO 19 2026 '!H27 -> -3328779.4
G11: REINTEGRO DE CAJA MENOR | H11: 4000000
H12: =SUM(H10:H11) -> 671220.56
A14: 5/20/2026 | B14: 93021861 | C14: PEDRO DUCUARA | D14: DOMICILIARIO | E14: DOMICILIO U.T | F14: 93021861 | G14: PEDRO DUCUARA | H14: 8000
A15: 5/20/2026 | B15: 65737477 | C15: SANDRA GALLEGO | D15: RECEPCION | E15: COMPRAS LONAS LOGISTICO | F15: 65735576-1 | G15: PLASTICOS LEYLA | H15: 2200
A16: 5/20/2026 | B16: 65777220 | C16: MAGDA TAFUR | D16: COMPRAS | E16: COMPRA SOUND TRACK IMPORTADOS | F16: 800251569 | G16: INTER RAPIDISIMO | H16: 43700
A17: 5/20/2026 | B17: 13239826 | C17: EDISON LEAL | D17: RECEPCION | E17: PARQUEADERO MENSAJERO | F17: 38225162 | G17: PARQUEADERO LA TERTULIA | H17: 900
A18: 5/20/2026 | B18: 93389605 | C18: GABRIEL GOMEZ | D18: LOGISTICO | E18: COMPRA BROCA LOGISTICA | F18: 14236816-8 | G18: FERRETERIA LAYA | H18: 14900
A19: 5/20/2026 | B19: 93389605 | C19: GABRIEL GOMEZ | D19: LOGISTICO | E19: COMPRA TORNILLERIA VARIADA LOGISTICA | F19: 901953761-4 | G19: SERVIRODRIGUEZ FERRETERIA | H19: 2400
A20: 5/20/2026 | B20: 65737477 | C20: SANDRA GALLEGO | D20: RECEPCION | E20: COMPRA COLADOR PARA GRECA CAFETERIA LEON | F20: 55151131-4 | G20: TODO RESPUESTOS DEL TOLIMA | H20: 23000
H27: =SUM(H14:H26) -> 95100
H29: =+H12-H27 -> 576120.56
B32: 110580597 | C32: WILIAN FELIPE | D32: PLANEACION
B33: 65777220 | C33: MAGDA TAFUR | D33: COMPRAS
B35: 14106438 | C35: DIEGO RADA | D35: CONTRATACION
B36: 5939109 | C36: MIRVEAN HERNANDEZ | D36: LOGISTICA
B37: 13239826 | C37: EDISON LEAL | D37: RECEPCION
B38: 65762110 | C38: SANDRA BONILLA | D38: CONTRATACION
B39: 1032372158 | C39: HAROLD FERIAS | D39: LOGISTICA
B40: 1110511708 | C40: FABIAN PEREZ | D40: INGENIERO
B41: 1110546445 | C41: MARIO GARCIA | D41: LOSGISTICA
B42: 1006123077 | C42: JOHAN GARZON | D42: AUXILIAR L.
B43: 14236999 | C43: JAIRO ARIAS | D43: PRODUCCION
B44: 1234638696 | C44: GIOUANNI HURTADO | D44: LOGISTICA
... B48: 1007832826 | C48: SEBASTIAN GONGORA | D48: PLANIACION
B49: 800185306-4 | C49: ENVIA
B50: 1110546445 | C50: MARIO GARCIA | D50: LOSGISTICA
B51: 1005717607 | C51: JIMY GUTIERREZ | D51: LOSGISTICA
B52: 14243741 | C52: JUAN HORTA | D52: PRODUCCION
B53: 1110442630 | C53: JERSSON OROZCO | D53: LOGISTICA
B54: 900276962-1 | C54: D1 SAS
B55: 800251569 | C55: INTERRAPIDISOMO
B56: 1006122533 | C56: LAURA MARIN | D56: COMUNICADORA
B57: 111046289 | C57: JHON CARDENAS | D57: LOGISTICA
B58: 28542010 | C58: ADRIANA NARVAEZ | D58: DIRECCION DE COSTOS

Sheet MAYO 21 2026
D1: CAJA MENOR
A7: FECHA | B7: CEDULA(NIT) | C7: NOMBRE | D7: FUNCIONARIO | E7: DESCRIPCIÓN O DETALLE | F7: NIT | G7: PROVEEDOR
H10: ='MAYO 20 2026 '!H29 -> 576120.56
A12: 46163 | B12: 65762110 | C12: SANDRA BONILLA | D12: CONTRATACION | E12: ENVIO HASH TICKET SA | F12: 800251569 | G12: INTERRAPIDISOMO | H12: 15000
A13: 46163 | B13: 14236999 | C13: JAIRO ARIAS | D13: PRODUCCION | E13: SOBRE BOND LORD 75GR | F13: 900241288-2 | G13: PAPELERIA LA COMUNA | H13: 14820
A14: 46163 | B14: 13239826 | C14: EDISON LEAL | D14: RECEPCION | E14: PARQUEADERO MENSAJERO | F14: 19494727-4 | G14: PARQUEADERO VARSOVIA | H14: 1600
A15: 46163 | B15: 13239826 | C15: EDISON LEAL | D15: RECEPCION | E15: PARQUEADERO MENSAJERO | F15: 901312036-2 | G15: PARQUEADERO M-TREINTA | H15: 4200
A16: 46163 | B16: 65737477 | C16: SANDRA GALLEGO | D16: RECEPCION | E16: COMPRA DE CALCULADORA | F16: 900241288-2 | G16: PAPELERIA LA COMUNA | H16: 12100
H18: =SUM(H12:H17) -> 47720
H20: =+H10-H18 -> 528400.56
B23: 110580597 | C23: WILIAN FELIPE | D23: PLANEACION
B24: 65777220 | C24: MAGDA TAFUR | D24: COMPRAS
B26: 14106438 | C26: DIEGO RADA | D26: CONTRATACION
B27: 5939109 | C27: MIRVEAN HERNANDEZ | D27: LOGISTICA
B28: 13239826 | C28: EDISON LEAL | D28: RECEPCION
B29: 65762110 | C29: SANDRA BONILLA | D29: CONTRATACION
B30: 1032372158 | C30: HAROLD FERIAS | D30: LOGISTICA
B31: 1110511708 | C31: FABIAN PEREZ | D31: INGENIERO
B32: 1110546445 | C32: MARIO GARCIA | D32: LOSGISTICA
B33: 1006123077 | C33: JOHAN GARZON | D33: AUXILIAR L.
B34: 14236999 | C34: JAIRO ARIAS | D34: PRODUCCION
B35: 1234638696 | C35: GIOUANNI HURTADO | D35: LOGISTICA
... B39: 1007832826 | C39: SEBASTIAN GONGORA | D39: PLANIACION
B40: 800185306-4 | C40: ENVIA
B41: 1110546445 | C41: MARIO GARCIA | D41: LOSGISTICA
B42: 1005717607 | C42: JIMY GUTIERREZ | D42: LOSGISTICA
B43: 14243741 | C43: JUAN HORTA | D43: PRODUCCION
B44: 1110442630 | C44: JERSSON OROZCO | D44: LOGISTICA
B45: 900276962-1 | C45: D1 SAS
B46: 800251569 | C46: INTERRAPIDISOMO
B47: 1006122533 | C47: LAURA MARIN | D47: COMUNICADORA
B48: 111046289 | C48: JHON CARDENAS | D48: LOGISTICA
B49: 28542010 | C49: ADRIANA NARVAEZ | D49: DIRECCION DE COSTOS

Sheet MAYO 22 2026
D1: CAJA MENOR
A7: FECHA | B7: CEDULA(NIT) | C7: NOMBRE | D7: FUNCIONARIO | E7: DESCRIPCIÓN O DETALLE | F7: NIT | G7: PROVEEDOR
H10: ='MAYO 21 2026'!H20 -> 528400.56
A12: 46164 | B12: 5939109 | C12: MIRVEAN HERNANDEZ | D12: LOGISTICA | E12: TAXI RIO BLANCO | F12: 5939109 | G12: MIRVEAN HERNANDEZ | H12: 10000
A13: 46164 | B13: 65737477 | C13: SANDRA GALLEGO | D13: RECEPCION | E13: DOMICILIO JUSSOS | F13: 65737477 | G13: SANDRA GALLEGO | H13: 12000
A14: 46164 | B14: 93389805 | C14: GABRIEL GOMEZ | D14: LOGISTICA | E14: TRANSPORTE LOGISTICA | F14: 93389805 | G14: GABRIEL GOMEZ | H14: 40000
A15: 46164 | B15: 65737477 | C15: SANDRA GALLEGO | D15: RECEPCION | E15: DOMICILIO 23 CON 6 A LEON PLANTA ELECTRICA | F15: 65737477 | G15: SANDRA GALLEGO | H15: 7000
A16: 46164 | B16: 13239826 | C16: EDISON LEAL | D16: RECEPCION | E16: TRANSPORTE MERCACENTRO EL POBLADO | F16: 13239826 | G16: EDISON LEAL | H16: 23000
A17: 46164 | B17: 65737477 | C17: SANDRA GALLEGO | D17: RECEPCION | E17: TAXI MEDICADIZ LEON | F17: 65737477 | G17: SANDRA GALLEGO | H17: 19300
A18: 46164 | B18: 65737477 | C18: SANDRA GALLEGO | D18: RECEPCION | E18: TAXI MEDICADIZ FUENTE REAL | F18: 65737477 | G18: SANDRA GALLEGO | H18: 19000
H20: =SUM(H12:H19) -> 130300
H22: =+H10-H20 -> 398100.56
B25: 110580597 | C25: WILIAN FELIPE | D25: PLANEACION
B26: 65777220 | C26: MAGDA TAFUR | D26: COMPRAS
B27: 65737477 | C27: SANDRA GALLEGO | D27: RECEPCION
B28: 14106438 | C28: DIEGO RADA | D28: CONTRATACION
B29: 5939109 | C29: MIRVEAN HERNANDEZ | D29: LOGISTICA
B30: 13239826 | C30: EDISON LEAL | D30: RECEPCION
B31: 65762110 | C31: SANDRA BONILLA | D31: CONTRATACION
B32: 1032372158 | C32: HAROLD FERIAS | D32: LOGISTICA
B33: 1110511708 | C33: FABIAN PEREZ | D33: INGENIERO
B34: 1110546445 | C34: MARIO GARCIA | D34: LOSGISTICA
B35: 1006123077 | C35: JOHAN GARZON | D35: AUXILIAR L.
B36: 14236999 | C36: JAIRO ARIAS | D36: PRODUCCION
... B41: 1007832826 | C41: SEBASTIAN GONGORA | D41: PLANIACION
B42: 800185306-4 | C42: ENVIA
B43: 1110546445 | C43: MARIO GARCIA | D43: LOSGISTICA
B44: 1005717607 | C44: JIMY GUTIERREZ | D44: LOSGISTICA
B45: 14243741 | C45: JUAN HORTA | D45: PRODUCCION
B46: 1110442630 | C46: JERSSON OROZCO | D46: LOGISTICA
B47: 900276962-1 | C47: D1 SAS
B48: 800251569 | C48: INTERRAPIDISOMO
B49: 1006122533 | C49: LAURA MARIN | D49: COMUNICADORA
B50: 111046289 | C50: JHON CARDENAS | D50: LOGISTICA
B51: 28542010 | C51: ADRIANA NARVAEZ | D51: DIRECCION DE COSTOS
B52: 93389805 | C52: GABRIEL GOMEZ | D52: LOGISTICA

Sheet MAYO 23 2026
D1: CAJA MENOR
A7: FECHA | B7: CEDULA(NIT) | C7: NOMBRE | D7: FUNCIONARIO | E7: DESCRIPCIÓN O DETALLE | F7: NIT | G7: PROVEEDOR
H10: ='MAYO 22 2026'!H22 -> 398100.56
A12: 46165 | B12: 65737477 | C12: SANDRA GALLEGO | D12: RECEPCION | E12: COMPRA FRUTA GERENCIA | F12: 901836157-4 | G12: DISTRIBUIDURA RAPRI | H12: 11264
A13: 46165 | B13: 1110511708 | C13: FABIAN PEREZ | D13: INGENIERO | E13: COMPRA DE SIM | F13: 1110511708 | G13: FABIAN PEREZ | H13: 4000
A14: 46165 | B14: 65777220 | C14: MAGDA TAFUR | D14: COMPRAS | E14: COMPRA TARRO BOLIGRAFO GERENCIA | F14: 65777220 | G14: MAGDA TAFUR | H14: 14000
A15: 46165 | B15: 65777220 | C15: MAGDA TAFUR | D15: COMPRAS | E15: TAXI VARIOS EVENTOS | F15: 65777220 | G15: MAGDA TAFUR | H15: 30000
A16: 46165 | B16: 65762110 | C16: SANDRA BONILLA | D16: CONTRATACION | E16: ALMUERZO 22 DE MAYO | F16: 65762110 | G16: SANDRA BONILLA | H16: 14000
A17: 46165 | B17: 5939109 | C17: MIRVEAN HERNANDEZ | D17: LOGISTICA | E17: TAXI C.C. LA ESTACION | F17: 5939109 | G17: MIRVEAN HERNANDEZ | H17: 8000
A18: 46165 | B18: 65737477 | C18: SANDRA GALLEGO | D18: RECEPCION | E18: ALMUERZO Y DESAYUNO MIRVEAN , GERENCIA | F18: 93391994 | G18: EL SAZON DE MARMEN | H18: 28000
A19: 46165 | B19: 65737477 | C19: SANDRA GALLEGO | D19: RECEPCION | E19: COMPRA DE PECES CABOMBA | F19: 5829503-0 | G19: AMAZONAS | H19: 5000
A20: 46165 | B20: 111046289 | C20: JHON CARDENAS | D20: LOGISTICA | E20: COMPRA CELULAR DE JHON CARDENAS | F20: 84089344-7 | G20: JHESVIER DE JESUS PEÑARANDA SPORCKEL | H20: 25000
A21: 46165 | B21: 65777220 | C21: MAGDA TAFUR | D21: COMPRAS | E21: EVENTO DIPLOMADO UT: INSTACREM Y BOLSAS | F21: 901768321 | G21: ARCINIEGAS ASOCIADOS | H21: 25860
H23: =SUM(H12:H22) -> 165124
H25: =+H10-H23 -> 232976.56
B28: 110580597 | C28: WILIAN FELIPE | D28: PLANEACION
B29: 65777220 | C29: MAGDA TAFUR | D29: COMPRAS
B30: 65737477 | C30: SANDRA GALLEGO | D30: RECEPCION
B31: 14106438 | C31: DIEGO RADA | D31: CONTRATACION
B32: 5939109 | C32: MIRVEAN HERNANDEZ | D32: LOGISTICA
B33: 13239826 | C33: EDISON LEAL | D33: RECEPCION
B34: 65762110 | C34: SANDRA BONILLA | D34: CONTRATACION
B35: 1032372158 | C35: HAROLD FERIAS | D35: LOGISTICA
B36: 1110511708 | C36: FABIAN PEREZ | D36: INGENIERO
B37: 1110546445 | C37: MARIO GARCIA | D37: LOSGISTICA
B38: 1006123077 | C38: JOHAN GARZON | D38: AUXILIAR L.
B39: 14236999 | C39: JAIRO ARIAS | D39: PRODUCCION
... B44: 1007832826 | C44: SEBASTIAN GONGORA | D44: PLANIACION
B45: 800185306-4 | C45: ENVIA
B46: 1110546445 | C46: MARIO GARCIA | D46: LOSGISTICA
B47: 1005717607 | C47: JIMY GUTIERREZ | D47: LOSGISTICA
B48: 14243741 | C48: JUAN HORTA | D48: PRODUCCION
B49: 1110442630 | C49: JERSSON OROZCO | D49: LOGISTICA
B50: 900276962-1 | C50: D1 SAS
B51: 800251569 | C51: INTERRAPIDISOMO
B52: 1006122533 | C52: LAURA MARIN | D52: COMUNICADORA
B53: 111046289 | C53: JHON CARDENAS | D53: LOGISTICA
B54: 28542010 | C54: ADRIANA NARVAEZ | D54: DIRECCION DE COSTOS
B55: 93389805 | C55: GABRIEL GOMEZ | D55: LOGISTICA
B56: 111046289 | C56: JHON CARDENAS | D56: LOGISTICA

Sheet MAYO 25 2026
D1: CAJA MENOR
A7: FECHA | B7: CEDULA(NIT) | C7: NOMBRE | D7: FUNCIONARIO | E7: DESCRIPCIÓN O DETALLE | F7: NIT | G7: PROVEEDOR
H10: ='MAYO 23 2026'!H25 -> 232976.56
A12: 46167 | B12: 1006123077 | C12: JOHAN GARZON | D12: AUXILIAR L. | E12: COMPRA DE ROLLO DE HELADO REUNION FOLCLOR | F12: 900480569-1 | G12: TIENDA ARA | H12: 17000
A13: 46167 | B13: 65777220 | C13: MAGDA TAFUR | D13: COMPRAS | E13: COMPRA PAÑITOS DAY COL EVENTO FULAN | F13: 1128470955-1 | G13: EL GANGAZO DE IBAGUE | H13: 12000
A14: 46167 | B14: 65777220 | C14: MAGDA TAFUR | D14: COMPRAS | E14: COMPRA SATIN RIGIDO EVENTO FULAN | F14: 93374325-1 | G14: ALMACEN EXITELAS | H14: 48000
A15: 46167 | B15: 65777220 | C15: MAGDA TAFUR | D15: COMPRAS | E15: COMPRA FAYA TRICOLOR 24MM EVENTO FULAN | F15: 65773968-7 | G15: SANDRA MILENA RAMIREZ | H15: 15120
A16: 46167 | B16: 65777220 | C16: MAGDA TAFUR | D16: COMPRAS | E16: COMPRA SUNDARK ADULTOS CAJA EVENTO FULAN | F16: 70504735-3 | G16: DISTRIBUIDORA EL IMPERIO | H16: 28700
A17: 46167 | B17: 65777220 | C17: MAGDA TAFUR | D17: COMPRAS | E17: COMPRA GEL ANTIBACTERIAL | F17: 65777220 | G17: MAGDA TAFUR | H17: 10000
A18: 46167 | B18: 65737477 | C18: SANDRA GALLEGO | D18: RECEPCION | E18: BASE LICUADORA UNIVERSAL ORIGINAL | F18: 1110530628-9 | G18: EL PALACIO DE LA LICUADORA Y VENTILADORES | H18: 35000
H20: =SUM(H12:H19) -> 165820
H22: =+H10-H20 -> 67156.56
B25: 110580597 | C25: WILIAN FELIPE | D25: PLANEACION
B26: 65777220 | C26: MAGDA TAFUR | D26: COMPRAS
B27: 65737477 | C27: SANDRA GALLEGO | D27: RECEPCION
B28: 14106438 | C28: DIEGO RADA | D28: CONTRATACION
B29: 5939109 | C29: MIRVEAN HERNANDEZ | D29: LOGISTICA
B30: 13239826 | C30: EDISON LEAL | D30: RECEPCION
B31: 65762110 | C31: SANDRA BONILLA | D31: CONTRATACION
B32: 1032372158 | C32: HAROLD FERIAS | D32: LOGISTICA
B33: 1110511708 | C33: FABIAN PEREZ | D33: INGENIERO
B34: 1110546445 | C34: MARIO GARCIA | D34: LOSGISTICA
B35: 1006123077 | C35: JOHAN GARZON | D35: AUXILIAR L.
B36: 14236999 | C36: JAIRO ARIAS | D36: PRODUCCION
... B41: 1007832826 | C41: SEBASTIAN GONGORA | D41: PLANIACION
B42: 800185306-4 | C42: ENVIA
B43: 1110546445 | C43: MARIO GARCIA | D43: LOSGISTICA
B44: 1005717607 | C44: JIMY GUTIERREZ | D44: LOSGISTICA
B45: 14243741 | C45: JUAN HORTA | D45: PRODUCCION
B46: 1110442630 | C46: JERSSON OROZCO | D46: LOGISTICA
B47: 900276962-1 | C47: D1 SAS
B48: 800251569 | C48: INTERRAPIDISOMO
B49: 1006122533 | C49: LAURA MARIN | D49: COMUNICADORA
B50: 111046289 | C50: JHON CARDENAS | D50: LOGISTICA
B51: 28542010 | C51: ADRIANA NARVAEZ | D51: DIRECCION DE COSTOS
B52: 93389805 | C52: GABRIEL GOMEZ | D52: LOGISTICA
B53: 111046289 | C53: JHON CARDENAS | D53: LOGISTICA
